Workbook
Name bspaym: [1]Mapping!$E$190:$H$252
Name Case_Status: [2]Reference!$I$3:$I$6
Name Case_Status: Reference!$I$3:$I$6
Name Category: [2]Reference!$G$3:$G$9
Name Category: Reference!$G$3:$G$9
Name code: #REF!
Name code: 'Enhancement '!#REF!
Name code: #REF!
Name Control_Points: #N/A
Name Date: #REF!
Name Date: 'Enhancement '!#REF!
Name Date: #REF!
Name Defect_Status: Reference!$D$3:$D$10
Name Defect_Tipification: Reference!$K$2:$K$4
Name DefectPriority: [2]Reference!$B$3:$B$5
Name DefectPriority: Reference!$B$3:$B$5
Name DefectStatus: [2]Reference!$D$3:$D$10
Name DefectStatus: Reference!$D$3:$D$10
Name DefectTipification: [2]Reference!$K$3:$K$4
Name DefectTipification: Reference!$K$3:$K$4
Name gl: [1]Mapping!$F$2:$F$252
Name Initializers: #N/A
Name jun: [3]tb!$L$1:$S$65536
Name NOT_STARTED: Reference!$I$3:$I$6
Name ohuk: #REF!
Name ohuk: 'Enhancement '!#REF!
Name ohuk: #REF!
Name Priority: Reference!$B$3:$B$5
Name Resolution_Resp: #N/A
Name Status: Reference!$D$3:$D$9
Name Sub_Test_Case_ID: #N/A
Name tb: #REF!
Name tb: 'Enhancement '!#REF!
Name tb: #REF!
Name TEST_CASE_ID: #N/A
Name TEST_CASE_ID: #N/A
Name TEST_CYCLE_ID: #N/A
Name TEST_CYCLE_ID: #N/A
Name TestCaseStatus: [2]Reference!$I$3:$I$6
Name TestCaseStatus: Reference!$I$3:$I$6
Name testcasestatuslist: Reference!$I$3:$I$6
Name version: #REF!
Name version: 'Enhancement '!#REF!
Name version: #REF!

Sheet Cover

Sheet Execution Report
B2: OVERALL TEST CASE STATUS | I2: OVERALL DEFECT STATUS | O2: OVERALL "OPEN" DEFECTS (i.e. New, Under Analysis, Working, Reopen) | U2: Defect classification type (i.e. Product Type" or "Implementation Type)
B3: CASE STATUS | C3: NR | D3: % | I3: DEFECT STATUS | J3: NR | K3: % | L3: NOTE | O3: DEFECT PRIORITY | P3: NR | Q3: % | U3: DEFECT TYPIFICATION | V3: NR | W3: %
B5: NOT STARTED | C5: =COUNTIF('Test Cycle Plan'!$F$3:G$181,'Execution Report'!B5) -> 10 | D5: =IF($C$13=0,0,C5/$C$13) -> 0.35714286 | I5: NEW | J5: =COUNTIF(Defects!L$2:L$793,'Execution Report'!I5) -> 2 | K5: =IF($J$13=0,0,J5/$J$13) -> 1 | L5: =Reference!E3 -> New issue raised | O5: HIGH | P5: {=SUM(IF(Defects!$E$2:$E$793=O5,IF(Defects!$L$2:$L$793="NEW",1,IF(Defects!$L$2:$L$793="UNDER ANALYSIS",1,IF(Defects!$L$2:$L$793="WORKING",1,IF(Defects!$L$2:$L$793="REOPEN",1,0)))),0))} -> 2 | Q5: =IF($P$13=0,0,P5/$P$13) -> 1 | U5: Product Type | V5: =COUNTIF(Defects!F$2:F$793,'Execution Report'!U5) -> 0 | W5: =IF($J$13=0,0,V5/$V$13) -> 0
B6: IN PROGRESS | C6: =COUNTIF('Test Cycle Plan'!$F$3:G$181,'Execution Report'!B6) -> 0 | D6: =IF($C$13=0,0,C6/$C$13) -> 0 | I6: =Reference!D4 -> UNDER ANALYSIS | J6: =COUNTIF(Defects!L$2:L$793,'Execution Report'!I6) -> 0 | K6: =IF($J$13=0,0,J6/$J$13) -> 0 | L6: =Reference!E4 -> Issue being analysed | O6: MEDIUM | P6: {=SUM(IF(Defects!$E$2:$E$793=O6,IF(Defects!$L$2:$L$793="NEW",1,IF(Defects!$L$2:$L$793="UNDER ANALYSIS",1,IF(Defects!$L$2:$L$793="WORKING",1,IF(Defects!$L$2:$L$793="REOPEN",1,0)))),0))} -> 0 | Q6: =IF($P$13=0,0,P6/$P$13) -> 0 | U6: Implementation type | V6: =COUNTIF(Defects!F$2:F$793,'Execution Report'!U6) -> 2 | W6: =IF($J$13=0,0,V6/$V$13) -> 1
B7: OK | C7: =COUNTIF('Test Cycle Plan'!$F$3:G$181,'Execution Report'!B7) -> 13 | D7: =IF($C$13=0,0,C7/$C$13) -> 0.46428571 | I7: =Reference!D5 -> WORKING | J7: =COUNTIF(Defects!L$2:L$793,'Execution Report'!I7) -> 0 | K7: =IF($J$13=0,0,J7/$J$13) -> 0 | L7: =Reference!E5 -> Fixing defect | O7: LOW | P7: {=SUM(IF(Defects!$E$2:$E$793=O7,IF(Defects!$L$2:$L$793="NEW",1,IF(Defects!$L$2:$L$793="UNDER ANALYSIS",1,IF(Defects!$L$2:$L$793="WORKING",1,IF(Defects!$L$2:$L$793="REOPEN",1,0)))),0))} -> 0 | Q7: =IF($P$13=0,0,P7/$P$13) -> 0
B8: NOK | C8: =COUNTIF('Test Cycle Plan'!$F$3:G$181,'Execution Report'!B8) -> 5 | D8: =IF($C$13=0,0,C8/$C$13) -> 0.17857143 | I8: =Reference!D6 -> REOPEN | J8: =COUNTIF(Defects!L$2:L$793,'Execution Report'!I8) -> 0 | K8: =IF($J$13=0,0,J8/$J$13) -> 0 | L8: =Reference!E6 -> Failed in retest
I9: =Reference!D7 -> POSTPONED | J9: =COUNTIF(Defects!L$2:L$793,'Execution Report'!I9) -> 0 | K9: =IF($J$13=0,0,J9/$J$13) -> 0 | L9: =Reference!E7 -> To be evaluated later | O9: Service Impact | P9: {=SUM(IF(Defects!$M$2:$P$598=O9,IF(Defects!$M$2:$M$598="Service Impact",1,IF(Defects!$M$2:$M$598="No Service Impact",1)),0))} -> 0 | Q9: =SUM(P8:P9)/100 -> 0
I10: =Reference!D8 -> REJECTED | J10: =COUNTIF(Defects!L$2:L$793,'Execution Report'!I10) -> 0 | K10: =IF($J$13=0,0,J10/$J$13) -> 0 | L10: =Reference!E8 -> Issue was rejected | O10: No Service Impact | P10: {=SUM(IF(Defects!$M$2:$P$598=O10,IF(Defects!$M$2:$M$598="Service Impact",1,IF(Defects!$M$2:$M$598="No Service Impact",1)),0))} -> 0 | Q10: =SUM(P9:P10)/100 -> 0
I11: =Reference!D9 -> FIXED | J11: =COUNTIF(Defects!L$2:L$793,'Execution Report'!I11) -> 0 | K11: =IF($J$13=0,0,J11/$J$13) -> 0 | L11: =Reference!E9 -> Ready for retest
I12: =Reference!D10 -> CLOSED | J12: =COUNTIF(Defects!L$2:L$793,'Execution Report'!I12) -> 0 | K12: =IF($J$13=0,0,J12/$J$13) -> 0 | L12: =Reference!E10 -> Retested OK
B13: TOTAL | C13: =SUM(C5:C8) -> 28 | D13: =SUM(D5:D8) -> 1 | I13: TOTAL | J13: =SUM(J5:J12) -> 2 | K13: =SUM(K5:K12) -> 1 | O13: TOTAL | P13: =SUM(P5:P9) -> 2 | Q13: =SUM(Q5:Q9) -> 1 | U13: TOTAL | V13: =SUM(V5:V9) -> 2 | W13: =SUM(W5:W9) -> 1

Sheet Test Cycle Plan
A3: TEST CYCLE | B3: STEP NUMBER | C3: STEP DESCRIPTION | D3: INPUT DATA | E3: EXPECTED RESULT | F3: ACTUAL STEP RESULT | G3: TEST CASE STATUS | H3: CATEGORY | I3: ASSIGNED_TO | J3: START DATE | K3: END DATE | L3: NR. OF EXECUTIONS | M3: COMPLETE SUCCESSFULLY % | N3: NOTES
A5: Portal
A6: TestID | B6: U1 | G6: OK | H6: Portal
A7: TestDescription | B7: User Management
A8: RequirementID
A9: Test Preconditions | B9: User should be able to login/logout to the RAID system
B10: 1 | C10: Login with your username and password | E10: User should be successfully logged in. | F10: User is able to login to the portal with username and password.
B11: 2 | C11: Click on the top right menu, select the "Sites & Pages" and select "Fraud Management" site | E11: Fraud Management site home page should be visible. | F11: User is able to see the fraud management site
B12: 3 | C12: Click on the "Sign Out" option located next to the "Manage Account" option at the bottom left corner of the side menu. | E12: User should be redirected to the login page after clicking on the "Sign Out" option | F12: User is getting redirected to login page once the user click on the sign out option
A13: TestID | B13: P1 | G13: OK | H13: Portal
A14: TestDescription | B14: Portal Navigation
A15: RequirementID
A16: Test Preconditions | B16: User should be able to see the portal tree
B17: 1 | C17: Fllowing links should be available in the left side menu BUSINESS OVERVIEW INBOX FRAUD MANAGEMENT Fraud Center Rules Management Rules Lists Engine Management Console INVESTIGATION CENTER Ad Hoc Queries Global Data search FINANCIAL REPORTS Fraud Amounts Fraud Loss BUSINESS STATISTICS Case Statistics Cases overview Cases reclassification Case events recovery Efficiency Analyst Statistics Team performance SLA Overview Rule Statistics Overview Effectiveness Performance Fraud Rule Optimizer Analysis OPERATIONAL REPORTS System Auditing Semaphore Control SYSTEM PARAMETERS Business Operational SETTINGS TOOLBOX Configuration Operational | E17: User should be able to see links and sub links while hovering the mouse on the left side menu | F17: User is able to see all required links in the portal.
E18: User should be able to click on the links
A19: TestID | B19: P2 | G19: OK | H19: Portal
A20: TestDescription | B20: Portal Navigation
A21: RequirementID
A22: Test Preconditions | B22: User should be able to see the online help
B23: 1 | C23: Click on the online help button (?) on the top right side of the screen | E23: User should be able to see the hyper links to the pages that contains the searched text | F23: User us able to see the hyper link that contains the searched text.
B24: 2 | C24: provide any text(E.g. "Loading" or "Lookups" etc ) and press enter | E24: On click on these hyperlinks, the user should be redirected to online help pages | F24: On click on the hyper links, the user is able to see the detailed information
A25: Loadings
A26: TestID | B26: L1 | G26: OK | H26: Loading
A27: TestDescription | B27: Loading :: Zain Ctrl LD MSC Eric -VOICE/SMS Evt Prs
A28: RequirementID | B28: Pre process Ericssion raw file.
A29: Test Preconditions | B29: Files are located in the input directories
B30: 1 | C30: Execute Control Loading Flow (Zain Ctrl LD MSC Eric -VOICE/SMS Evt Prs) to do pre parsing | D30: Sample files | E30: No errors occured during execution
B31: 2 | C31: Validate target directories have correct output: /appsdata/rafm_data/data/loading/msc/in /appsdata/rafm_data/data/loading/smsc/in | E31: Files exist on target directories and have correct format and output
A32: TestID | B32: L2 | G32: NOK | H32: Loading
A33: TestDescription | B33: Loading :: WDT Ctrl LD MSC
A34: RequirementID | B34: Enrichment of Voice Events.
A35: Test Preconditions | B35: Files are located in the input directories
B36: 1 | C36: Execute Control Loading Flow (WDT Ctrl LD MSC) to do loading for Voice Events. | D36: Sample files | E36: No errors occured during execution | F36: No errors observed during the execution
B37: 2 | C37: Validate the processed files are moved to the below folder: /appsdata/rafm_data/data/loading/msc/out | E37: Processed files should be moved to out directory | F37: Processed files moved to out dir
B38: 3 | C38: Validate target directories have correct output for Detection flows /appsdata/rafm_data/datafms/detection/subscribers/events/in/ /appsdata/rafm_data/datafms/detection/offnet_subscribers/events/in/ | E38: Files exist on target directories and have correct format and output, Detection files generated by MSC loading flow should start with DET_MSC_. File should be compressed. | F38: Files existing on target directory
B39: 4 | C39: Navigate to Ad hoc queries and apply filter to fetch processed record. | E39: Processed record should be visible. | F39: processed records are available in IWB
B40: 5 | C40: Navigate to Global Data search (data section). | E40: Processed record should be visible.
B41: 6 | C41: Check for the validity of failed events for the file processed. | E41: Only Valid rejections should be there.
A42: TestID | B42: L3 | G42: NOK | H42: Loading
A43: TestDescription | B43: Loading :: WDT Ctrl LD SMSC
...

Sheet Defects
A1: DEFECT ID | B1: TEST CASE ID/NAME | C1: INITIALIZER | D1: DEFECT DESCRIPTION | E1: PRIORITY | F1: DEFECT TYPIFICATION | G1: COMMENTS / HISTORY | H1: RESOLUTION ACTIONS | I1: RESOLUTION RESPONSIBLE | J1: DEFECT DETECTED ON DATE | K1: ACTUAL RESOLUTION DATE | L1: STATUS | M1: Service Impact
A2: 1 | B2: L2 | D2: MSC records are getting rejected with following error. 1. an error related to lookup Error executing statement Lookup (name=WDT Tariffs) . Reason: Index DESTINATION_PREFIX for lookup named WDT Tariffs doesnt allow null values at wedo.jaf.smarttransform2.engine.StandardEngine.execute(StandardEngine.java:119) 2. wedo.jaf.cbpm.flow.ProcessErrorException: Error executing task Business Logic due to Error executing statement Set (Flow::VAR_IMEI_LAST_DIGIT = $Right({Flow::VAR_IMEI},1)). Reason: Error while evaluating WEL Expression: [$Right({Flow::VAR_IMEI}, 1)] | E2: High | F2: Implementation type | J2: 17-06-2025 | L2: NEW
A3: 2 | B3: L3 | D3: Number normalization is not properly happening for offnet events B Number: 00962796608074 expected to have without 00 | E3: High | F3: Implementation type | J3: 18-06-2025 | L3: NEW

Sheet Enhancement 
A1: Enhancement ID | B1: Requirment Summary | C1: Raised By | D1: Requirment Details | E1: PRIORITY | F1: COMMENTS / HISTORY | G1: STATUS | H1: CLOSED BY

Sheet Reference
B2: Priority | D2: Defect Status | E2: Description | G2: Category name | I2: Case Status | K2: Defect Tipification
B3: High | D3: NEW | E3: New issue raised | G3: Loading | I3: NOT STARTED | K3: Product Type
B4: Medium | D4: UNDER ANALYSIS | E4: Issue being analysed | G4: Dashboard | I4: IN PROGRESS | K4: Implementation type
B5: Low | D5: WORKING | E5: Fixing defect | G5: Common Test Case | I5: OK
D6: REOPEN | E6: Failed in retest | G6: Case Management | I6: NOK
D7: POSTPONED | E7: To be evaluated later | I7: DISCARDED
D8: REJECTED | E8: Issue was rejected
D9: FIXED | E9: Ready for retest
D10: CLOSED | E10: Retested OK

Sheet Changes required
A2: L2 | B2: WDT Ctrl LD MSC
B3: need to check whether the tasks such as DS IMEI, DS ROAMERS /appsdata/rafm_data/datastore/imei/1 - 155 GB
B4: Few records are getting discard because of the B Number format issue. rdr_CALLED_PARTY_NUMBER (String) "119627959641980962795964198" do we need to inform customer or is it some valid scenario
A5: L3
B6: Some times the A NUMBER is not looking correct for SMSMT events. 12397737
B7: Short code related cases need to be cleaned and add a permanent fix to remove the short code related alerts
